<?xml version="1.0"?>
<robot xmlns:xacro="http://ros.org/wiki/xacro">

  <xacro:include filename="$(find aubo_description)/urdf/aubo_i5_transmission.xacro" />
  <xacro:include filename="$(find aubo_description)/urdf/aubo_i5_gazebo.xacro" />

  <xacro:macro name="aubo_i5"
    params="
  prefix 
  parent
  hw_interface:=hardware_interface/EffortJointInterface
  *origin"
  >

    <xacro:aubo_i5_transmission prefix="${prefix}" hw_interface="${hw_interface}" />
    <xacro:aubo_i5_gazebo prefix="${prefix}" />

    <!-- INERTIA -->
    <xacro:macro name="I5_BaseLink_Inertia">
      <origin xyz="1.1888811586008421e-07 0.0015716172771383882 0.020944607206477398" rpy="0 0 0" />
      <mass value="0.83419" />
      <inertia ixx="${0.011226*0.12799542569}" iyy="${0.010532*0.12799542569}"
        izz="${0.019183*0.12799542569}" ixy="-0.0" iyz="${-0.000114*0.12799542569}" ixz="-0.0" />
    </xacro:macro>
    <xacro:macro name="I5_Shoulder_Inertia">
      <origin xyz="0.0 0.006 -0.002" rpy="0 0 0" />
      <mass value="5.05" />
      <inertia ixx="0.0148" ixy="0" ixz="0" iyy="0.0143" iyz="-0.0" izz="0.0095" />
    </xacro:macro>
    <xacro:macro name="I5_UpperArm_Inertia">
      <origin xyz="0.20400000738607602 0.0003079721588177273 0.020108705518388777" rpy="0 0 0" />
      <mass value="11.90" />
      <inertia ixx="${0.133789*0.21958145116}" iyy="${1.548798*0.21958145116}"
        izz="${1.5133*0.21958145116}" ixy="${-0.0*0.21958145116}" iyz="${2.3e-05*0.21958145116}"
        ixz="${0.0*0.21958145116}" />
    </xacro:macro>
    <xacro:macro name="I5_ForeArm_Inertia">
      <origin xyz="0.18880713458962045 8.0702133231828e-06 0.09802927852704038" rpy="0 0 0" />
      <mass value="3.3" />
      <inertia ixx="${0.016448*0.18731379107}" iyy="${0.345066*0.18731379107}" izz="${0.343039*0.18731379107}" ixy="${1.3e-05*0.18731379107}" iyz="${2e-06*0.18731379107}"
        ixz="${-0.005687*0.18731379107}" />
    </xacro:macro>
    <xacro:macro name="I5_Wrist1_Inertia">
      <origin xyz="0.0 0.0028 -0.003" rpy="0 0 0" />
      <mass value="1.62" />
      <inertia ixx="0.0023" ixy="0" ixz="0" iyy="0.0013" iyz="0.0" izz="0.0022" />
    </xacro:macro>
    <xacro:macro name="I5_Wrist2_Inertia">
      <origin xyz="0.0 -0.0028 -0.003" rpy="0 0 0" />
      <mass value="1.62" />
      <inertia ixx="0.0023" ixy="0" ixz="0" iyy="0.0013" iyz="0.0" izz="0.0022" />
    </xacro:macro>
    <xacro:macro name="I5_Wrist3_Inertia">
        <origin xyz="3.8199537218366924e-05 -6.891283689656669e-05 -0.021357543727161605" rpy="0 0 0"/>
        <mass value="${1.2143524682183242*0.32939365667}"/>
        <inertia ixx="${0.000545*0.32939365667}" iyy="${0.000549*0.32939365667}" izz="${0.000814*0.32939365667}" ixy="${-0.0*0.32939365667}" iyz="${0.0*0.32939365667}" ixz="${-0.0*0.32939365667}"/>
    </xacro:macro>

    <!-- LINKS -->
    <link name="${prefix}aubo_i5_base_link">
      <inertial>
        <xacro:I5_BaseLink_Inertia />
      </inertial>
      <visual>
        <origin xyz="0 0 0" rpy="0 0 0" />
        <geometry>
          <mesh filename="package://aubo_description/meshes/aubo_i5/visual/base_link.DAE" />
        </geometry>
        <material name="">
          <color rgba="1 1 1 1" />
        </material>
      </visual>
      <collision>
        <origin xyz="0 0 0" rpy="0 0 0" />
        <geometry>
          <mesh filename="package://aubo_description/meshes/aubo_i5/collision/base_link.STL" />
        </geometry>
      </collision>
    </link>
    <link name="${prefix}shoulder_link">
      <inertial>
        <xacro:I5_Shoulder_Inertia />
      </inertial>
      <visual>
        <origin xyz="0 0 0" rpy="0 0 0" />
        <geometry>
          <mesh filename="package://aubo_description/meshes/aubo_i5/visual/shoulder_Link.DAE" />
        </geometry>
        <material name="">
          <color rgba="1 1 1 1" />
        </material>
      </visual>
      <collision>
        <origin xyz="0 0 0" rpy="0 0 0" />
        <geometry>
          <mesh filename="package://aubo_description/meshes/aubo_i5/collision/shoulder_Link.STL" />
        </geometry>
      </collision>
    </link>
    <link name="${prefix}upper_arm_link">
      <inertial>
        <xacro:I5_UpperArm_Inertia />
      </inertial>
      <visual>
        <origin xyz="0 0 0" rpy="0 0 0" />
        <geometry>
          <mesh filename="package://aubo_description/meshes/aubo_i5/visual/upperArm_Link.DAE" />
        </geometry>
        <material name="">
          <color rgba="1 1 1 1" />
        </material>
      </visual>
      <collision>
        <origin xyz="0 0 0" rpy="0 0 0" />
        <geometry>
          <mesh filename="package://aubo_description/meshes/aubo_i5/collision/upperArm_Link.STL" />
        </geometry>
      </collision>
    </link>
    <link name="${prefix}forearm_link">
      <inertial>
        <xacro:I5_ForeArm_Inertia />
      </inertial>
      <visual>
        <origin xyz="0 0 0" rpy="0 0 0" />
        <geometry>
          <mesh filename="package://aubo_description/meshes/aubo_i5/visual/foreArm_Link.DAE" />
        </geometry>
        <material name="">
          <color rgba="1 1 1 1" />
        </material>
      </visual>
      <collision>
        <origin xyz="0 0 0" rpy="0 0 0" />
        <geometry>
          <mesh filename="package://aubo_description/meshes/aubo_i5/collision/foreArm_Link.STL" />
        </geometry>
      </collision>
    </link>
    <link name="${prefix}wrist_1_link">
      <inertial>
        <xacro:I5_Wrist1_Inertia />
      </inertial>
      <visual>
        <origin xyz="0 0 0" rpy="0 0 0" />
        <geometry>
          <mesh filename="package://aubo_description/meshes/aubo_i5/visual/wrist1_Link.DAE" />
        </geometry>
        <material name="">
          <color rgba="1 1 1 1" />
        </material>
      </visual>
      <collision>
        <origin xyz="0 0 0" rpy="0 0 0" />
        <geometry>
          <mesh filename="package://aubo_description/meshes/aubo_i5/collision/wrist1_Link.STL" />
        </geometry>
      </collision>
    </link>
    <link name="${prefix}wrist_2_link">
      <inertial>
        <xacro:I5_Wrist2_Inertia />
      </inertial>
      <visual>
        <origin xyz="0 0 0" rpy="0 0 0" />
        <geometry>
          <mesh filename="package://aubo_description/meshes/aubo_i5/visual/wrist2_Link.DAE" />
        </geometry>
        <material name="">
          <color rgba="1 1 1 1" />
        </material>
      </visual>
      <collision>
        <origin xyz="0 0 0" rpy="0 0 0" />
        <geometry>
          <mesh filename="package://aubo_description/meshes/aubo_i5/collision/wrist2_Link.STL" />
        </geometry>
      </collision>
    </link>
    <link name="${prefix}wrist_3_link">
      <inertial>
        <xacro:I5_Wrist3_Inertia />
      </inertial>
      <visual>
        <origin xyz="0 0 0" rpy="0 0 0" />
        <geometry>
          <mesh filename="package://aubo_description/meshes/aubo_i5/visual/wrist3_Link.DAE" />
        </geometry>
        <material name="">
          <color rgba="1 1 1 1" />
        </material>
      </visual>
      <collision>
        <origin xyz="0 0 0" rpy="0 0 0" />
        <geometry>
          <mesh filename="package://aubo_description/meshes/aubo_i5/collision/wrist3_Link.STL" />
        </geometry>
      </collision>
    </link>

    <!-- JOINTS -->
    <joint name="${prefix}shoulder_pan_joint" type="revolute">
      <origin xyz="0 0 0.122" rpy="0 0 3.1416" />
      <parent link="${prefix}aubo_i5_base_link" />
      <child link="${prefix}shoulder_link" />
      <axis xyz="0 0 1" />
      <limit lower="-3.04" upper="3.04" effort="150" velocity="${pi}" />
    </joint>
    <joint name="${prefix}shoulder_lift_joint" type="revolute">
      <origin xyz="0 0.1215 0" rpy="-1.5708 -1.5708 0" />
      <parent link="${prefix}shoulder_link" />
      <child link="${prefix}upper_arm_link" />
      <axis xyz="0 0 1" />
      <limit lower="-3.04" upper="3.04" effort="150" velocity="${pi}" />
    </joint>
    <joint name="${prefix}elbow_joint" type="revolute">
      <origin xyz="0.408 0 0" rpy="-3.1416 -5.1632E-18 -5.459E-16" />
      <parent link="${prefix}upper_arm_link" />
      <child link="${prefix}forearm_link" />
      <axis xyz="0 0 1" />
      <limit lower="-3.04" upper="3.04" effort="150" velocity="${pi}" />
    </joint>
    <joint name="${prefix}wrist_1_joint" type="revolute">
      <origin xyz="0.376 0 0" rpy="3.1416 -1.8323E-15 1.5708" />
      <parent link="${prefix}forearm_link" />
      <child link="${prefix}wrist_1_link" />
      <axis xyz="0 0 1" />
      <limit lower="-3.04" upper="3.04" effort="28" velocity="${pi}" />
    </joint>
    <joint name="${prefix}wrist_2_joint" type="revolute">
      <origin xyz="0 0.1025 0" rpy="-1.5708 -1.8709E-15 -1.6653E-16" />
      <parent link="${prefix}wrist_1_link" />
      <child link="${prefix}wrist_2_link" />
      <axis xyz="0 0 1" />
      <limit lower="-3.04" upper="3.04" effort="28" velocity="${pi}" />
    </joint>
    <joint name="${prefix}wrist_3_joint" type="revolute">
      <origin xyz="0 -0.094 0" rpy="1.5708 0 1.7907E-15" />
      <parent link="${prefix}wrist_2_link" />
      <child link="${prefix}wrist_3_link" />
      <axis xyz="0 0 1" />
      <limit lower="-3.04" upper="3.04" effort="28" velocity="${pi}" />
    </joint>


    <link name="${prefix}ee_link">
      <collision>
        <geometry>
          <box size="0.01 0.01 0.01" />
        </geometry>
        <origin rpy="0 0 0" xyz="-0.01 0 0" />
      </collision>
    </link>
    <joint name="${prefix}ee_fixed_joint" type="fixed">
      <parent link="${prefix}wrist_3_link" />
      <child link="${prefix}ee_link" />
      <origin rpy="${pi} ${-pi/2} ${pi/2}" xyz="0.0 0.0 0.0" />
    </joint>

    <joint name="${prefix}aubo_i5_base_joint" type="fixed">
      <parent link="${parent}" />
      <child link="${prefix}aubo_i5_base_link" />
      <xacro:insert_block name="origin" />
    </joint>
  </xacro:macro>

</robot>